Workbook
Name cem: Tableau1[cem]
Name dida: Tableau1[e/dida]
Name dr: Tableau1[directio]
Name ep: Tableau1[ep]
Name info: Tableau1[e/infortq]
Name lyc: Tableau1[lycee]
Name pdr: Tableau1[[pdr ]]
Name Segment_etablisement: #N/A
Name Segment_re_nre: #N/A
Name Segment_re_nre1: #N/A
Name Segment_re_nre2: #N/A
Name Segment_technicien: #N/A
Name Segment_technicien1: #N/A
Name Segment_technicien2: #N/A
Name tech: Tableau1[[nom technicien ]]
Name topo: Tableau1[e/topo]
Name wilaya: Tableau1[wilya]

Sheet Acceuil
M3: type equipement
F4: totale/eq | M4: rec | N4: rep | O4: nrp
E5: recut | F5: =Informatique!J1+Topograpique!J1+Didactique!J1 -> 27 | L5: info | M5: =Informatique!J1 -> 5 | N5: =Informatique!K1 -> 0 | O5: =Informatique!L1 -> 5
E6: reparee | F6: =Informatique!K1+Topograpique!K1+Didactique!K1 -> 17 | L6: topo | M6: =Topograpique!J1 -> 13 | N6: =Topograpique!K1 -> 8 | O6: =Topograpique!L1 -> 5
E7: n_rep | F7: =Informatique!L1+Topograpique!L1+Didactique!L1 -> 10 | L7: dida | M7: =Didactique!J1 -> 9 | N7: =Didactique!K1 -> 9 | O7: =Didactique!L1 -> 0
G25: rec | H25: rep | I25: n-rep
F26: ep | G26: =Tableau2[[#Totals],[rec]]+Tableau27[[#Totals],[rec]]+Tableau211[[#Totals],[rec]] -> 5 | H26: =Tableau2[[#Totals],[re]]+Tableau27[[#Totals],[re]]+Tableau211[[#Totals],[re]] -> 2 | I26: =Tableau2[[#Totals],[nr]]+Tableau27[[#Totals],[nr]]+Tableau211[[#Totals],[nr]] -> 3
F27: cem | G27: =Tableau24[[#Totals],[rec]]+Tableau248[[#Totals],[rec]]+Tableau2412[[#Totals],[rec]] -> 3 | H27: =Tableau24[[#Totals],[re]]+Tableau248[[#Totals],[re]]+Tableau2412[[#Totals],[re]] -> 2 | I27: =Tableau24[[#Totals],[nr]]+Tableau248[[#Totals],[nr]]+Tableau2412[[#Totals],[nr]] -> 1
F28: lyc | G28: =Tableau245[[#Totals],[rec]]+Tableau2459[[#Totals],[rec]]+Tableau24513[[#Totals],[rec]] -> 13 | H28: =Tableau245[[#Totals],[re]]+Tableau2459[[#Totals],[re]]+Tableau24513[[#Totals],[re]] -> 9 | I28: =Tableau245[[#Totals],[nr]]+Tableau2459[[#Totals],[nr]]+Tableau24513[[#Totals],[nr]] -> 4
F29: D-ed | G29: =Tableau2456[[#Totals],[rec]]+Tableau245610[[#Totals],[rec]]+Tableau245614[[#Totals],[rec]] -> 6 | H29: =Tableau2456[[#Totals],[re]]+Tableau245610[[#Totals],[re]]+Tableau245614[[#Totals],[re]] -> 4 | I29: =Tableau2456[[#Totals],[nr]]+Tableau245610[[#Totals],[nr]]+Tableau245614[[#Totals],[nr]] -> 2
F30: totale | G30: =SUM(G26:G29) -> 27 | H30: =SUM(H26:H29) -> 17 | I30: =SUM(I26:I29) -> 10

Sheet Liste de donnees
E2: liste des donnees
E5: nom technicien | F5: wilya | G5: nbr | H5: ep | I5: cem | J5: lycee | K5: directio | L5: pdr | M5: e/infortq | N5: e/topo | O5: e/dida
E6: obeid ben said | F6: saida | G6: 1 | H6: chahid djabar chikh | I6: brahmi mohamed | J6: houari boumedien | K6: d -education | L6: boite alimentation | M6: unite central | N6: photocopieur | O6: datashow
E7: hafnaoui samir | F7: el bayadh | G7: 1 | H7: barket mohamed | J7: mhamed boukhobza | K7: pay | L7: fusible | M7: imprimante | N7: duplicateur | O7: empermetre
E8: amara mostefa | F8: timimoun | G8: 1 | H8: naouari housin | L8: eclataire | M8: onduleur | O8: voltmetre
E9: ouimeur norddine | F9: adrar | G9: 1 | H9: youcefi ben chrit | L9: dalle 18pouss | M9: tablette | O9: balance
E10: hossam mokhtari | G10: 1 | H10: hamidi hamza | L10: dalle21 pousse | M10: not book | O10: emplificateur
E11: ghaout mohamed | G11: 1 | H11: naamaoui ben youcef | L11: ecran complet | M11: scanner | O11: alimentation-s
E12: mezian amine | G12: 1 | H12: bousssag djelloul | L12: carte alimentation | O12: microscop-avec ecran
E13: aouar abdekrim | G13: 1 | H13: daygham | L13: battrie | O13: fax
G14: 1 | H14: rzazgui boualem | L14: aficheur tablette | O14: microscop
G15: 1 | H15: abdeli ramdan | L15: ecran tactile
G16: 1 | H16: zani mohamed | L16: disque dure
G17: =SUBTOTAL(109,Tableau1[nbr]) -> 11

Sheet Informatique
J1: =Tableau2[[#Totals],[rec]]+Tableau24[[#Totals],[rec]]+Tableau245[[#Totals],[rec]]+Tableau2456[[#Totals],[rec]] -> 5 | K1: =Tableau2[[#Totals],[re]]+Tableau24[[#Totals],[re]]+Tableau245[[#Totals],[re]]+Tableau2456[[#Totals],[re]] -> 0 | L1: =Tableau2[[#Totals],[nr]]+Tableau24[[#Totals],[nr]]+Tableau245[[#Totals],[nr]]+Tableau2456[[#Totals],[nr]] -> 5
E2: equipement des ecole primaire | J2: recut | K2: reparee | L2: n_repree
E5: equipement | F5: marque | G5: inventaire | H5: n serie | I5: etablisement | J5: wilaya | K5: commune | L5: date recp | M5: panne | N5: technicien | O5: operation | P5: pdr | Q5: reference | R5: qt | S5: re/nre | T5: date env | U5: rec | V5: re | W5: nr
E6: tablette | F6: enie | G6: skte119e | H6: 202305007291 | I6: hamidi hamza | J6: el bayadh | K6: rogassa | L6: 45950 | M6: battrie | N6: ghaout mohamed | O6: chargement battrie | R6: 0 | S6: oui | T6: 45950 | U6: 1 | V6: 1 | W6: 0
E7: tablette | F7: enie | G7: skte119e | H7: 202305007066 | I7: hamidi hamza | J7: el bayadh | K7: rogassa | L7: 45950 | M7: battrie | N7: aouar abdekrim | O7: chargement battrie | P7: battrie | S7: non | T7: 45950 | U7: 1 | V7: 0 | W7: 1
E8: tablette | F8: enie | G8: skte119e | H8: 202305007054 | I8: hamidi hamza | J8: el bayadh | K8: rogassa | L8: 45950 | M8: battrie | N8: ghaout mohamed | O8: chargement battrie | P8: battrie | S8: non | T8: 45950 | U8: 1 | V8: 0 | W8: 1
E9: tablette | F9: enie | G9: skte119e | H9: 2022028645 | I9: naouari housin | J9: el bayadh | K9: boualem | L9: 45950 | M9: serveur | N9: aouar abdekrim | O9: mise a jour maktabati | S9: oui | T9: 45950 | U9: 1 | V9: 1 | W9: 0
E10: tablette | F10: enie | G10: skt706 | H10: 2022047241 | I10: barket mohamed | J10: el bayadh | K10: boualem | L10: 45950 | M10: syst | N10: ghaout mohamed | O10: mise a jour maktabati | S10: oui | T10: 45950 | U10: 1 | V10: 1 | W10: 0
E11: tablette | F11: enie | G11: skt706 | H11: 2022022315 | I11: barket mohamed | J11: el bayadh | K11: boualem | L11: 45950 | M11: syst | N11: aouar abdekrim | O11: mise a jour maktabati | S11: oui | T11: 45950 | U11: 1 | V11: 1 | W11: 0
E12: tablette | F12: enie | G12: skt706 | H12: 2022045055 | I12: barket mohamed | J12: el bayadh | K12: boualem | L12: 45950 | M12: syst | N12: ghaout mohamed | O12: mise a jour maktabati | S12: oui | T12: 45950 | U12: 1 | V12: 1 | W12: 0
E13: tablette | F13: enie | G13: skte119e | H13: 202305001838 | I13: naamaoui ben youcef | J13: el bayadh | K13: chellala | L13: 45950 | M13: syst | N13: aouar abdekrim | O13: mise a jour maktabati | S13: oui | T13: 45950 | U13: 1 | V13: 1 | W13: 0
E14: tablette | F14: enie | G14: skte119e | H14: 202305001709 | I14: youcefi ben chrit | J14: el bayadh | K14: a arak | L14: 45950 | M14: livre | N14: ghaout mohamed | O14: instalation livre | S14: oui | T14: 45950 | U14: 1 | V14: 1 | W14: 0
E15: tablette | F15: enie | G15: skte119e | H15: 202305001524 | I15: youcefi ben chrit | J15: el bayadh | K15: a arak | L15: 45950 | M15: livre | N15: aouar abdekrim | O15: instalation livre | S15: oui | T15: 45950 | U15: 1 | V15: 1 | W15: 0
E16: tablette | F16: enie | G16: skte119e | H16: 202305001802 | I16: chahid djabar chikh | J16: el bayadh | K16: stiten | L16: 45950 | M16: battrie | N16: ghaout mohamed | O16: chargement | S16: oui | T16: 45950 | U16: 1 | V16: 1 | W16: 0
E17: tablette | F17: enie | G17: skte119e | H17: 2023005001497 | I17: chahid djabar chikh | J17: el bayadh | K17: stiten | L17: 45950 | M17: battrie | N17: aouar abdekrim | O17: charement battrie | S17: oui | T17: 45950 | U17: 1 | V17: 1 | W17: 0
E18: tablette | F18: enie | G18: skte119e | H18: 2023005001583 | I18: chahid djabar chikh | J18: el bayadh | K18: stiten | L18: 45950 | M18: batrie | N18: ghaout mohamed | O18: chargement batrie | S18: oui | T18: 45950 | U18: 1 | V18: 1 | W18: 0
E19: tablette | F19: enie | G19: skte119e | H19: 2023005001634 | I19: chahid djabar chikh | J19: el bayadh | K19: stiten | L19: 45950 | M19: ecran digital non fonctionel | N19: aouar abdekrim | O19: ecran digital | S19: non | T19: 45950 | U19: 1 | V19: 0 | W19: 1
E20: tablette | F20: enie | G20: skte119e | H20: 2023005001804 | I20: chahid djabar chikh | J20: el bayadh | K20: stiten | L20: 45950 | M20: battrie | N20: ghaout mohamed | O20: chargement | S20: oui | T20: 45950 | U20: 1 | V20: 1 | W20: 0
... E23: tablette | F23: enie | G23: skte119e | H23: 2023005001635 | I23: chahid djabar chikh | J23: el bayadh | K23: stiten | L23: 45950 | M23: batrie | N23: aouar abdekrim | O23: chargement | S23: oui | T23: 45950 | U23: 1 | V23: 0 | W23: 1
E24: tablette | F24: enie | G24: skte119e | H24: 2023005001800 | I24: chahid djabar chikh | J24: el bayadh | K24: stiten | L24: 45950 | M24: battrie | N24: ghaout mohamed | O24: chargement | P24: battrie | R24: 0 | S24: oui | T24: 45950 | U24: 1 | V24: 0 | W24: 1
E25: tablette | F25: enie | G25: skte119e | H25: 2023005001438 | I25: chahid djabar chikh | J25: el bayadh | K25: stiten | L25: 45950 | M25: soft | N25: aouar abdekrim | O25: mise a jour maktabati | S25: oui | T25: 45950 | U25: 1 | V25: 1 | W25: 0
E26: tablette | F26: enie | G26: skte119e | H26: 2023005001580 | I26: chahid djabar chikh | J26: el bayadh | K26: stiten | L26: 45950 | M26: afficheur | N26: aouar abdekrim | P26: aficheur tablette | R26: 0 | S26: non | T26: 45950 | U26: 1 | V26: 0 | W26: 1
E27: scanner | F27: hp | G27: scanjet | H27: 310/1347/1710 | I27: chahid djabar chikh | J27: el bayadh | K27: stiten | L27: 45950 | M27: fixation des visse | N27: ghaout mohamed | S27: oui | T27: 45950 | U27: 1 | V27: 1 | W27: 0
E28: tablette | F28: enie | G28: skte119e | H28: 2022028890 | I28: bousssag djelloul | J28: el bayadh | K28: bougtob | L28: 45950 | M28: ecran tactile non fonctionel | N28: aouar abdekrim | P28: ecran tactile | S28: non | T28: 45950 | U28: 1 | V28: 0 | W28: 1
E29: tablette | F29: enie | G29: skte119e | H29: 202202928 | I29: bousssag djelloul | J29: el bayadh | K29: bougtob | L29: 45950 | M29: ecran tactile non fonctionel | N29: ghaout mohamed | P29: ecran tactile | R29: 0 | S29: non | T29: 45950 | U29: 1 | V29: 0 | W29: 1
E30: tablette | F30: enie | G30: skte119e | H30: 2022028890 | I30: bousssag djelloul | J30: el bayadh | K30: bougtob | L30: 45950 | M30: bouton tablette | N30: aouar abdekrim | O30: fixation du boutton | R30: 0 | S30: oui | T30: 45950 | U30: 1 | V30: 1 | W30: 0
E31: tablette | F31: enie | G31: skte119e | H31: 2022028840 | I31: bousssag djelloul | J31: el bayadh | K31: bougtob | L31: 45950 | M31: livre english | N31: ghaout mohamed | O31: instalation livre | S31: oui | T31: 45950 | U31: 1 | V31: 1 | W31: 0
E32: tablette | F32: enie | G32: skte119e | H32: 2022028849 | I32: bousssag djelloul | J32: el bayadh | K32: bougtob | L32: 45950 | M32: livre english | N32: aouar abdekrim | O32: instalation livre | S32: oui | T32: 45950 | U32: 1 | V32: 1 | W32: 0
E33: tablette | F33: enie | G33: skt706 | H33: 222053953 | I33: daygham | J33: el bayadh | K33: arbaouet | L33: 45950 | N33: ghaout mohamed | O33: activation compte eleve | S33: oui | T33: 45950 | U33: 1 | V33: 1 | W33: 0
E34: tablette | F34: enie | G34: skte119e | H34: 2022028483 | I34: rzazgui boualem | J34: el bayadh | K34: boualem | L34: 45950 | M34: batrie | N34: aouar abdekrim | O34: chargement | P34: battrie | R34: 0 | S34: non | T34: 45950 | U34: 1 | V34: 0 | W34: 1
E35: tablette | F35: enie | G35: skte119e | H35: 2022028598 | I35: rzazgui boualem | J35: el bayadh | K35: boualem | L35: 45951 | M35: batrie | N35: ghaout mohamed | O35: chargement | S35: oui | T35: 45950 | U35: 1 | V35: 1 | W35: 0
E36: tablette | F36: enie | G36: skte119e | H36: 2022028581 | I36: rzazgui boualem | J36: el bayadh | K36: boualem | L36: 45952 | M36: batrie | N36: aouar abdekrim | O36: chargement | P36: battrie | R36: 0 | S36: non | T36: 45950 | U36: 1 | V36: 0 | W36: 1
E37: unite central | F37: del | G37: optiplex 3020 | H37: fhxhj32 | I37: daygham | J37: el bayadh | K37: arbaouet | L37: 45950 | N37: ghaout mohamed | S37: oui | T37: 45950 | U37: 1 | V37: 1 | W37: 0
E38: unite central | F38: hp | G38: elit desk | H38: czc4523h8r | I38: daygham | J38: el bayadh | K38: arbaouet | L38: 45950 | N38: aouar abdekrim | S38: oui | T38: 45950 | U38: 1 | V38: 1 | W38: 0
E39: tablette | F39: enie | G39: skt119 | H39: 20230500273 | I39: abdeli ramdan | J39: el bayadh | K39: tosmolin | L39: 45950 | N39: ghaout mohamed | S39: oui | U39: 1 | V39: 1 | W39: 0
E40: tablette | F40: enie | G40: skt119 | H40: 20230500264 | I40: abdeli ramdan | J40: el bayadh | K40: tosmolin | L40: 45950 | N40: aouar abdekrim | S40: oui | U40: 1 | V40: 1 | W40: 0
E41: tablette | F41: enie | G41: skt119 | H41: 20230500281 | I41: abdeli ramdan | J41: el bayadh | K41: tosmolin | L41: 45950 | N41: ghaout mohamed | S41: oui | U41: 1 | V41: 1 | W41: 0
E42: tablette | F42: enie | G42: skt119 | H42: 20230500256 | I42: abdeli ramdan | J42: el bayadh | K42: tosmolin | L42: 45950 | N42: aouar abdekrim | O42: mise a jour maktabati | S42: oui | U42: 1 | V42: 1 | W42: 0
E43: tablette | F43: enie | G43: skt119 | H43: 20230500259 | I43: abdeli ramdan | J43: el bayadh | K43: tosmolin | L43: 45950 | N43: ghaout mohamed | S43: oui | U43: 1 | V43: 1 | W43: 0
E44: tablette | F44: enie | G44: skt119 | H44: 20230500258 | I44: abdeli ramdan | J44: el bayadh | K44: tosmolin | L44: 45950 | N44: aouar abdekrim | S44: oui | U44: 1 | V44: 1 | W44: 0
...

Sheet Topograpique
J1: =Tableau27[[#Totals],[rec]]+Tableau248[[#Totals],[rec]]+Tableau2459[[#Totals],[rec]]+Tableau245610[[#Totals],[rec]] -> 13 | K1: =Tableau27[[#Totals],[re]]+Tableau248[[#Totals],[re]]+Tableau2459[[#Totals],[re]]+Tableau245610[[#Totals],[re]] -> 8 | L1: =Tableau27[[#Totals],[nr]]+Tableau248[[#Totals],[nr]]+Tableau2459[[#Totals],[nr]]+Tableau245610[[#Totals],[nr]] -> 5
J2: recut | K2: reparee | L2: n_repree
E3: equipement des ecole primaire
E5: equipement | F5: marque | G5: inventaire | H5: n serie | I5: etablisement | J5: wilaya | K5: commune | L5: date recp | M5: panne | N5: technicien | O5: operation | P5: pdr | Q5: reference | R5: qt | S5: re/nre | T5: date env | U5: rec | V5: re | W5: nr
E6: photocopieur | F6: kyocera | G6: m2135 | H6: ig/1261 | I6: youcefi ben chrit | J6: el bayadh | K6: a arak | L6: 45953 | N6: ouimeur norddine | O6: nettoyage | S6: oui | T6: 45953 | U6: 1 | V6: 1 | W6: 0
E7: photocopieur | F7: kyocera | G7: fs1120mfp | H7: v3v7901634 | I7: zani mohamed | J7: el bayadh | K7: bougtob | L7: 45951 | N7: obeid ben said | S7: oui | T7: 45953 | U7: 1 | V7: 1 | W7: 0
U8: 0 | V8: 0 | W8: 0
U9: 0 | V9: 0 | W9: 0
U10: =SUBTOTAL(109,Tableau27[rec]) -> 2 | V10: =SUBTOTAL(109,Tableau27[re]) -> 2 | W10: =SUBTOTAL(109,Tableau27[nr]) -> 0
E16: equipement des cem
E18: equipement | F18: marque | G18: inventaire | H18: n serie | I18: etablisement | J18: wilaya | K18: commune | L18: date recp | M18: panne | N18: technicien | O18: operation | P18: pdr | Q18: reference | R18: qt | S18: re/nre | T18: date env | U18: rec | V18: re | W18: nr
E19: duplicateur | F19: ricoh | G19: ig/690 | H19: dx2430 | I19: brahmi mohamed | J19: el bayadh | K19: ghassoul | L19: 45950 | N19: obeid ben said | S19: non | T19: pris | U19: 1 | V19: 0 | W19: 1
E20: photocopieur | F20: ricoh | G20: ig/0037 | H20: mp2014p | I20: brahmi mohamed | J20: el bayadh | K20: ghassoul | L20: 45950 | N20: ouimeur norddine | S20: oui | T20: pris | U20: 1 | V20: 1 | W20: 0
U21: 0 | V21: 0 | W21: 0
U22: 0 | V22: 0 | W22: 0
U23: =SUBTOTAL(109,Tableau248[rec]) -> 2 | V23: =SUBTOTAL(109,Tableau248[re]) -> 1 | W23: =SUBTOTAL(109,Tableau248[nr]) -> 1
E26: equipement des lycee
E28: equipement | F28: marque | G28: inventaire | H28: n serie | I28: etablisement | J28: wilaya | K28: commune | L28: date recp | M28: panne | N28: technicien | O28: operation | P28: pdr | Q28: reference | R28: qt | S28: re/nre | T28: date env | U28: rec | V28: re | W28: nr
E29: photocopieur | F29: taskalfa 180 | G29: ig/11572 | I29: mhamed boukhobza | J29: el bayadh | K29: elbayadh | L29: 45949 | M29: ras | N29: ouimeur norddine | S29: oui | U29: 1 | V29: 1 | W29: 0
E30: duplicateur | F30: rong gd04 | G30: vr231 | H30: 2312012530 | I30: mhamed boukhobza | J30: el bayadh | K30: elbayadh | L30: 45949 | N30: obeid ben said | S30: non | U30: 1 | V30: 0 | W30: 1
E31: photocopieur | F31: kyocera | G31: km1635 | I31: houari boumedien | J31: el bayadh | K31: elbayadh | L31: 45949 | N31: ouimeur norddine | S31: non | U31: 1 | V31: 0 | W31: 1
E32: photocopieur | F32: panasonic | I32: houari boumedien | J32: el bayadh | K32: elbayadh | L32: 45949 | N32: obeid ben said | S32: non | U32: 1 | V32: 0 | W32: 1
U33: =SUBTOTAL(109,Tableau2459[rec]) -> 4 | V33: =SUBTOTAL(109,Tableau2459[re]) -> 1 | W33: =SUBTOTAL(109,Tableau2459[nr]) -> 3
E36: equipement dautre direction
E38: equipement | F38: marque | G38: inventaire | H38: n serie | I38: etablisement | J38: wilaya | K38: commune | L38: date recp | M38: panne | N38: technicien | O38: operation | P38: pdr | Q38: reference | R38: qt | S38: re/nre | T38: date env | U38: rec | V38: re | W38: nr
E39: photocopieur | F39: taskalfa | G39: 180 | H39: 1102kl3nl | I39: d -education | J39: el bayadh | K39: el bayadh | L39: 45949 | N39: obeid ben said | S39: non | U39: 1 | V39: 0 | W39: 1
E40: photocopieur | F40: kyocera | G40: m20350dn | H40: lvq560941 | I40: d -education | J40: el bayadh | K40: el bayadh | L40: 45949 | N40: ouimeur norddine | S40: oui | U40: 1 | V40: 1 | W40: 0
E41: photocopieur | F41: kyocera | G41: fs1120 | H41: r7g8202362 | I41: d -education | J41: el bayadh | K41: el bayadh | L41: 45949 | N41: obeid ben said | S41: oui | U41: 1 | V41: 1 | W41: 0
E42: photocopieur | F42: canon | G42: ir 2124 | H42: ig1911 | I42: d -education | J42: el bayadh | K42: el bayadh | L42: 45949 | N42: ouimeur norddine | S42: oui | U42: 1 | V42: 1 | W42: 0
E43: photocopieur | F43: canon | G43: ir2206 | H43: 2fai7277 | I43: d -education | J43: el bayadh | K43: el bayadh | L43: 45949 | N43: obeid ben said | S43: oui | U43: 1 | V43: 1 | W43: 0
U44: 0 | V44: 0 | W44: 0
U45: =SUBTOTAL(109,Tableau245610[rec]) -> 5 | V45: =SUBTOTAL(109,Tableau245610[re]) -> 4 | W45: =SUBTOTAL(109,Tableau245610[nr]) -> 1

Sheet Didactique
J1: =Tableau211[[#Totals],[rec]]+Tableau2412[[#Totals],[rec]]+Tableau24513[[#Totals],[rec]]+Tableau245614[[#Totals],[rec]] -> 9 | K1: =Tableau211[[#Totals],[re]]+Tableau2412[[#Totals],[re]]+Tableau24513[[#Totals],[re]]+Tableau245614[[#Totals],[re]] -> 9 | L1: =Tableau211[[#Totals],[nr]]+Tableau2412[[#Totals],[nr]]+Tableau24513[[#Totals],[nr]]+Tableau245614[[#Totals],[nr]] -> 0
E2: equipement des ecole primaire | J2: recut | K2: reparee | L2: n_repree
E5: equipement | F5: marque | G5: inventaire | H5: n serie | I5: etablisement | J5: wilaya | K5: commune | L5: date recp | M5: panne | N5: technicien | O5: operation | P5: pdr | Q5: reference | R5: qt | S5: re/nre | T5: date env | U5: rec | V5: re | W5: nr
U6: 0 | V6: 0 | W6: 0
U7: 0 | V7: 0 | W7: 0
U8: 0 | V8: 0 | W8: 0
U9: 0 | V9: 0 | W9: 0
U10: =SUBTOTAL(109,Tableau211[rec]) -> 0 | V10: =SUBTOTAL(109,Tableau211[re]) -> 0 | W10: =SUBTOTAL(109,Tableau211[nr]) -> 0
E16: equipement des cem
E18: equipement | F18: marque | G18: inventaire | H18: n serie | I18: etablisement | J18: wilaya | K18: commune | L18: date recp | M18: panne | N18: technicien | O18: operation | P18: pdr | Q18: reference | R18: qt | S18: re/nre | T18: date env | U18: rec | V18: re | W18: nr
E19: fax | G19: 924 | I19: brahmi mohamed | J19: el bayadh | K19: ghassoul | L19: 45949 | N19: obeid ben said | S19: oui | U19: 1 | V19: 1 | W19: 0
U20: 0 | V20: 0 | W20: 0
U21: 0 | V21: 0 | W21: 0
U22: 0 | V22: 0 | W22: 0
U23: =SUBTOTAL(109,Tableau2412[rec]) -> 1 | V23: =SUBTOTAL(109,Tableau2412[re]) -> 1 | W23: =SUBTOTAL(109,Tableau2412[nr]) -> 0
E26: equipement des lycee
E28: equipement | F28: marque | G28: inventaire | H28: n serie | I28: etablisement | J28: wilaya | K28: commune | L28: date recp | M28: panne | N28: technicien | O28: operation | P28: pdr | Q28: reference | R28: qt | S28: re/nre | T28: date env | U28: rec | V28: re | W28: nr
E29: microscop-avec ecran | F29: presser | G29: presser | H29: ig/g6419 | I29: houari boumedien | J29: el bayadh | K29: el bayadh | L29: 45949 | M29: ras | N29: obeid ben said | O29: fait | S29: oui | T29: 45949 | U29: 1 | V29: 1 | W29: 0
E30: microscop-avec ecran | F30: presser | G30: presser | H30: ig/g6119 | I30: houari boumedien | J30: el bayadh | K30: el bayadh | L30: 45949 | M30: ras | N30: amara mostefa | O30: fait | S30: oui | T30: 45949 | U30: 1 | V30: 1 | W30: 0
E31: microscop-avec ecran | F31: presser | G31: presser | H31: ig/g8293 | I31: houari boumedien | J31: el bayadh | K31: el bayadh | L31: 45949 | M31: ras | N31: obeid ben said | O31: fait | S31: oui | T31: 45949 | U31: 1 | V31: 1 | W31: 0
E32: microscop | F32: xp103a | G32: xsp103 | H32: 4711 | I32: houari boumedien | J32: el bayadh | K32: el bayadh | L32: 45949 | M32: ras | N32: amara mostefa | S32: oui | T32: 45949 | U32: 1 | V32: 1 | W32: 0
E33: microscop | F33: xp103a | G33: xsp104 | H33: 6322 | I33: houari boumedien | J33: el bayadh | K33: el bayadh | L33: 45949 | M33: ras | N33: obeid ben said | S33: oui | T33: 45949 | U33: 1 | V33: 1 | W33: 0
E34: microscop | F34: xp103a | G34: xsp105 | H34: 6320 | I34: houari boumedien | J34: el bayadh | K34: el bayadh | L34: 45949 | M34: ras | N34: amara mostefa | S34: oui | T34: 45949 | U34: 1 | V34: 1 | W34: 0
E35: microscop | F35: xp103a | G35: xsp106 | H35: 3518 | I35: houari boumedien | J35: el bayadh | K35: el bayadh | L35: 45949 | M35: ras | N35: obeid ben said | S35: oui | T35: 45949 | U35: 1 | V35: 1 | W35: 0
E36: microscop | F36: xp103a | G36: xsp107 | H36: 634 | I36: houari boumedien | J36: el bayadh | K36: el bayadh | L36: 45949 | M36: ras | N36: amara mostefa | S36: oui | T36: 45949 | U36: 1 | V36: 1 | W36: 0
U37: =SUBTOTAL(109,Tableau24513[rec]) -> 8 | V37: =SUBTOTAL(109,Tableau24513[re]) -> 8 | W37: =SUBTOTAL(109,Tableau24513[nr]) -> 0
E40: equipement dautre direction
E42: equipement | F42: marque | G42: inventaire | H42: n serie | I42: etablisement | J42: wilaya | K42: commune | L42: date recp | M42: panne | N42: technicien | O42: operation | P42: pdr | Q42: reference | R42: qt | S42: re/nre | T42: date env | U42: rec | V42: re | W42: nr
U43: 0 | V43: 0 | W43: 0
U44: 0 | V44: 0 | W44: 0
U45: 0 | V45: 0 | W45: 0
U46: 0 | V46: 0 | W46: 0
U47: =SUBTOTAL(109,Tableau245614[rec]) -> 0 | V47: =SUBTOTAL(109,Tableau245614[re]) -> 0 | W47: =SUBTOTAL(109,Tableau245614[nr]) -> 0

Sheet intervention enie
E2: Intervetion enie tablette
E5: etablisement | F5: marchee | G5: model | H5: n serie | I5: date | J5: panne signales | K5: defau constate | L5: tache efectuees | M5: pdr remplace | N5: reference | O5: qt
D6: 1 | E6: abdeli ramdan | F6: 2023 | G6: enie skt119e | H6: 202305000927 | I6: 45950 | J6: system+ maktabati | K6: flash tool+maktabati | L6: flash tool+maktabati | O6: 0
D7: 2 | E7: abdeli ramdan | F7: 2023 | G7: enie skt119e | H7: 202305003596 | I7: 45950 | J7: maktabati | K7: maktabati | L7: instalation+validation | O7: 0
D8: 3 | E8: abdeli ramdan | F8: 2023 | G8: enie skt119e | H8: 202305000657 | I8: 45950 | J8: maktabati | K8: maktabati | L8: instalation+validation | O8: 0
D9: 4 | E9: abdeli ramdan | F9: 2023 | G9: enie skt119e | H9: 202305000954 | I9: 45950 | J9: battrie+ maktabati | K9: battrie | L9: chagement battrie+maktabati | M9: battrie | O9: 1
D10: 5 | E10: abdeli ramdan | F10: 2023 | G10: enie skt119e | H10: 202305002747 | I10: 45950 | J10: maktabati | K10: maktabati | L10: instalation+validation | O10: 0
D11: 6 | E11: abdeli ramdan | F11: 2023 | G11: enie skt119e | H11: 202305003609 | I11: 45950 | J11: battrie+ maktabati | K11: battrie | L11: chagement battrie+maktabati | M11: battrie | O11: 1
D12: 7 | E12: abdeli ramdan | F12: 2023 | G12: enie skt119e | H12: 202305000949 | I12: 45950 | J12: battrie | K12: battrie | L12: chagement battrie+maktabati | M12: battrie | O12: 1
D13: 8 | E13: abdeli ramdan | F13: 2023 | G13: enie skt119e | H13: 202305000767 | I13: 45950 | J13: battrie | K13: battrie | L13: chagement battrie+maktabati | M13: battrie | O13: 1
D14: 9 | E14: abdeli ramdan | F14: 2023 | G14: enie skt119e | H14: 202305000292 | I14: 45950 | J14: maktabati | K14: maktabati | L14: instalation+validation | O14: 0
D15: 10 | E15: abdeli ramdan | F15: 2023 | G15: enie skt119e | H15: 202305003590 | I15: 45950 | J15: maktabati | K15: maktabati | L15: instalation+validation | O15: 0
D16: 11 | E16: abdeli ramdan | F16: 2023 | G16: enie skt119e | H16: 202305002192 | I16: 45950 | J16: battrie | K16: battrie | L16: chagement battrie | M16: battrie | O16: 1
D17: 12 | E17: abdeli ramdan | F17: 2023 | G17: enie skt119e | H17: 202305003517 | I17: 45950 | J17: qr code | K17: flash tool+maktabati | L17: flash tool+maktabati | O17: 0
D18: 13 | E18: abdeli ramdan | F18: 2023 | G18: enie skt119e | H18: 202305000750 | I18: 45950 | J18: qr code | K18: flash tool+maktabati | L18: flash tool+maktabati | O18: 0
D19: 14 | E19: abdeli ramdan | F19: 2023 | G19: enie skt119e | H19: 202305000451 | I19: 45950 | J19: qr code | K19: flash tool+maktabati | L19: flash tool+maktabati | O19: 0
D20: 15 | E20: abdeli ramdan | F20: 2023 | G20: enie skt119e | H20: 202305003603 | I20: 45950 | J20: battrie | K20: battrie | L20: chagement battrie | M20: battrie | O20: 1
D21: 16 | E21: abdeli ramdan | F21: 2023 | G21: enie skt119e | H21: 202305003587 | I21: 45950 | J21: battrie | K21: battrie | L21: chagement battrie | M21: battrie | O21: 1
D22: 17 | E22: abdeli ramdan | F22: 2023 | G22: enie skt119e | H22: 202305003055 | I22: 45950 | J22: qr code | K22: flash tool+maktabati | L22: flash tool+maktabati | O22: 0
D23: 18 | E23: abdeli ramdan | F23: 2023 | G23: enie skt119e | H23: 202305003056 | I23: 45950 | J23: qr code | K23: flash tool+maktabati | L23: flash tool+maktabati | O23: 0
D24: 19 | E24: abdeli ramdan | F24: 2023 | G24: enie skt119e | H24: 202305000795 | I24: 45950 | J24: maktabati | K24: maktabati | L24: instalation+validation | O24: 0
